Workbook

Sheet Big Board (by rank)
A1: Wide Left Consensus Big Board
A2: Compiled by Arif Hasan (@ArifHasanNFL)
A3: Find out more at wideleft.football
A4: Ovr | B4: Fore | C4: Eval | D4: Player | E4: School | F4: Position | G4: Pos Rk | H4: Variance | I4: Pick | J4: Team
A5: =SUMIF('Bigger Board'!D:D,D5,'Bigger Board'!A:A) -> 1 | B5: =SUMIF('Bigger Board'!D:D,D5,'Bigger Board'!B:B) -> 1 | C5: =SUMIF('Bigger Board'!D:D,D5,'Bigger Board'!C:C) -> 1 | D5: Fernando Mendoza | E5: Indiana | F5: QB | G5: =SUMIF('Bigger Board'!D:D,D5,'Bigger Board'!G:G) -> 1 | H5: =SUMIF('Bigger Board'!D:D,D5,'Bigger Board'!H:H) -> 99.1 | I5: 1 | J5: Las Vegas Raiders
A6: =SUMIF('Bigger Board'!D:D,D6,'Bigger Board'!A:A) -> 2 | B6: =SUMIF('Bigger Board'!D:D,D6,'Bigger Board'!B:B) -> 2 | C6: =SUMIF('Bigger Board'!D:D,D6,'Bigger Board'!C:C) -> 3 | D6: Arvell Reese | E6: Ohio State | F6: LB | G6: =SUMIF('Bigger Board'!D:D,D6,'Bigger Board'!G:G) -> 1 | H6: =SUMIF('Bigger Board'!D:D,D6,'Bigger Board'!H:H) -> 75.7 | I6: 5 | J6: New York Giants
A7: =SUMIF('Bigger Board'!D:D,D7,'Bigger Board'!A:A) -> 3 | B7: =SUMIF('Bigger Board'!D:D,D7,'Bigger Board'!B:B) -> 3 | C7: =SUMIF('Bigger Board'!D:D,D7,'Bigger Board'!C:C) -> 2 | D7: Jeremiyah Love | E7: Notre Dame | F7: RB | G7: =SUMIF('Bigger Board'!D:D,D7,'Bigger Board'!G:G) -> 1 | H7: =SUMIF('Bigger Board'!D:D,D7,'Bigger Board'!H:H) -> 76.5 | I7: 3 | J7: Arizona Cardinals
A8: =SUMIF('Bigger Board'!D:D,D8,'Bigger Board'!A:A) -> 4 | B8: =SUMIF('Bigger Board'!D:D,D8,'Bigger Board'!B:B) -> 5 | C8: =SUMIF('Bigger Board'!D:D,D8,'Bigger Board'!C:C) -> 4 | D8: Caleb Downs | E8: Ohio State | F8: S | G8: =SUMIF('Bigger Board'!D:D,D8,'Bigger Board'!G:G) -> 1 | H8: =SUMIF('Bigger Board'!D:D,D8,'Bigger Board'!H:H) -> 79.7 | I8: 11 | J8: Dallas Cowboys
A9: =SUMIF('Bigger Board'!D:D,D9,'Bigger Board'!A:A) -> 5 | B9: =SUMIF('Bigger Board'!D:D,D9,'Bigger Board'!B:B) -> 6 | C9: =SUMIF('Bigger Board'!D:D,D9,'Bigger Board'!C:C) -> 5 | D9: Sonny Styles | E9: Ohio State | F9: LB | G9: =SUMIF('Bigger Board'!D:D,D9,'Bigger Board'!G:G) -> 2 | H9: =SUMIF('Bigger Board'!D:D,D9,'Bigger Board'!H:H) -> 76.5 | I9: 7 | J9: Washington Commanders
A10: =SUMIF('Bigger Board'!D:D,D10,'Bigger Board'!A:A) -> 6 | B10: =SUMIF('Bigger Board'!D:D,D10,'Bigger Board'!B:B) -> 8 | C10: =SUMIF('Bigger Board'!D:D,D10,'Bigger Board'!C:C) -> 6 | D10: Rueben Bain Jr. | E10: Miami (FL) | F10: EDGE | G10: =SUMIF('Bigger Board'!D:D,D10,'Bigger Board'!G:G) -> 1 | H10: =SUMIF('Bigger Board'!D:D,D10,'Bigger Board'!H:H) -> 84.3 | I10: 15 | J10: Tampa Bay Buccaneers
A11: =SUMIF('Bigger Board'!D:D,D11,'Bigger Board'!A:A) -> 7 | B11: =SUMIF('Bigger Board'!D:D,D11,'Bigger Board'!B:B) -> 4 | C11: =SUMIF('Bigger Board'!D:D,D11,'Bigger Board'!C:C) -> 7 | D11: David Bailey | E11: Texas Tech | F11: EDGE | G11: =SUMIF('Bigger Board'!D:D,D11,'Bigger Board'!G:G) -> 2 | H11: =SUMIF('Bigger Board'!D:D,D11,'Bigger Board'!H:H) -> 86 | I11: 2 | J11: New York Jets
A12: =SUMIF('Bigger Board'!D:D,D12,'Bigger Board'!A:A) -> 8 | B12: =SUMIF('Bigger Board'!D:D,D12,'Bigger Board'!B:B) -> 7 | C12: =SUMIF('Bigger Board'!D:D,D12,'Bigger Board'!C:C) -> 10 | D12: Francis Mauigoa | E12: Miami (FL) | F12: OT | G12: =SUMIF('Bigger Board'!D:D,D12,'Bigger Board'!G:G) -> 1 | H12: =SUMIF('Bigger Board'!D:D,D12,'Bigger Board'!H:H) -> 79.2 | I12: 10 | J12: New York Giants
A13: =SUMIF('Bigger Board'!D:D,D13,'Bigger Board'!A:A) -> 9 | B13: =SUMIF('Bigger Board'!D:D,D13,'Bigger Board'!B:B) -> 9 | C13: =SUMIF('Bigger Board'!D:D,D13,'Bigger Board'!C:C) -> 9 | D13: Carnell Tate | E13: Ohio State | F13: WR | G13: =SUMIF('Bigger Board'!D:D,D13,'Bigger Board'!G:G) -> 1 | H13: =SUMIF('Bigger Board'!D:D,D13,'Bigger Board'!H:H) -> 79.2 | I13: 4 | J13: Tennessee Titans
A14: =SUMIF('Bigger Board'!D:D,D14,'Bigger Board'!A:A) -> 10 | B14: =SUMIF('Bigger Board'!D:D,D14,'Bigger Board'!B:B) -> 10 | C14: =SUMIF('Bigger Board'!D:D,D14,'Bigger Board'!C:C) -> 8 | D14: Mansoor Delane | E14: LSU | F14: CB | G14: =SUMIF('Bigger Board'!D:D,D14,'Bigger Board'!G:G) -> 1 | H14: =SUMIF('Bigger Board'!D:D,D14,'Bigger Board'!H:H) -> 71.1 | I14: 6 | J14: Kansas City Chiefs
A15: =SUMIF('Bigger Board'!D:D,D15,'Bigger Board'!A:A) -> 11 | B15: =SUMIF('Bigger Board'!D:D,D15,'Bigger Board'!B:B) -> 11 | C15: =SUMIF('Bigger Board'!D:D,D15,'Bigger Board'!C:C) -> 11 | D15: Spencer Fano | E15: Utah | F15: OT | G15: =SUMIF('Bigger Board'!D:D,D15,'Bigger Board'!G:G) -> 2 | H15: =SUMIF('Bigger Board'!D:D,D15,'Bigger Board'!H:H) -> 84.2 | I15: 9 | J15: Cleveland Browns
A16: =SUMIF('Bigger Board'!D:D,D16,'Bigger Board'!A:A) -> 12 | B16: =SUMIF('Bigger Board'!D:D,D16,'Bigger Board'!B:B) -> 12 | C16: =SUMIF('Bigger Board'!D:D,D16,'Bigger Board'!C:C) -> 14 | D16: Makai Lemon | E16: USC | F16: WR | G16: =SUMIF('Bigger Board'!D:D,D16,'Bigger Board'!G:G) -> 2 | H16: =SUMIF('Bigger Board'!D:D,D16,'Bigger Board'!H:H) -> 82.4 | I16: 20 | J16: Philadelphia Eagles
... A120: =SUMIF('Bigger Board'!D:D,D120,'Bigger Board'!A:A) -> 116 | B120: =SUMIF('Bigger Board'!D:D,D120,'Bigger Board'!B:B) -> 124 | C120: =SUMIF('Bigger Board'!D:D,D120,'Bigger Board'!C:C) -> 114 | D120: Markel Bell | E120: Miami (FL) | F120: OT | G120: =SUMIF('Bigger Board'!D:D,D120,'Bigger Board'!G:G) -> 10 | H120: =SUMIF('Bigger Board'!D:D,D120,'Bigger Board'!H:H) -> 107.3 | I120: 68 | J120: Philadelphia Eagles
A121: =SUMIF('Bigger Board'!D:D,D121,'Bigger Board'!A:A) -> 117 | B121: =SUMIF('Bigger Board'!D:D,D121,'Bigger Board'!B:B) -> 137 | C121: =SUMIF('Bigger Board'!D:D,D121,'Bigger Board'!C:C) -> 115 | D121: Deontae Lawson | E121: Alabama | F121: LB | G121: =SUMIF('Bigger Board'!D:D,D121,'Bigger Board'!G:G) -> 9 | H121: =SUMIF('Bigger Board'!D:D,D121,'Bigger Board'!H:H) -> 116.8
A122: =SUMIF('Bigger Board'!D:D,D122,'Bigger Board'!A:A) -> 118 | B122: =SUMIF('Bigger Board'!D:D,D122,'Bigger Board'!B:B) -> 118 | C122: =SUMIF('Bigger Board'!D:D,D122,'Bigger Board'!C:C) -> 116 | D122: Michael Trigg | E122: Baylor | F122: TE | G122: =SUMIF('Bigger Board'!D:D,D122,'Bigger Board'!G:G) -> 7 | H122: =SUMIF('Bigger Board'!D:D,D122,'Bigger Board'!H:H) -> 101
A123: =SUMIF('Bigger Board'!D:D,D123,'Bigger Board'!A:A) -> 119 | B123: =SUMIF('Bigger Board'!D:D,D123,'Bigger Board'!B:B) -> 111 | C123: =SUMIF('Bigger Board'!D:D,D123,'Bigger Board'!C:C) -> 117 | D123: Will Lee III | E123: Texas A&M | F123: CB | G123: =SUMIF('Bigger Board'!D:D,D123,'Bigger Board'!G:G) -> 17 | H123: =SUMIF('Bigger Board'!D:D,D123,'Bigger Board'!H:H) -> 83.8 | I123: 129 | J123: Carolina Panthers
A124: =SUMIF('Bigger Board'!D:D,D124,'Bigger Board'!A:A) -> 120 | B124: =SUMIF('Bigger Board'!D:D,D124,'Bigger Board'!B:B) -> 112 | C124: =SUMIF('Bigger Board'!D:D,D124,'Bigger Board'!C:C) -> 119 | D124: Tacario Davis | E124: Washington | F124: CB | G124: =SUMIF('Bigger Board'!D:D,D124,'Bigger Board'!G:G) -> 18 | H124: =SUMIF('Bigger Board'!D:D,D124,'Bigger Board'!H:H) -> 96.9 | I124: 72 | J124: Cincinnati Bengals
A125: =SUMIF('Bigger Board'!D:D,D125,'Bigger Board'!A:A) -> 121 | B125: =SUMIF('Bigger Board'!D:D,D125,'Bigger Board'!B:B) -> 120 | C125: =SUMIF('Bigger Board'!D:D,D125,'Bigger Board'!C:C) -> 122 | D125: Drew Allar | E125: Penn State | F125: QB | G125: =SUMIF('Bigger Board'!D:D,D125,'Bigger Board'!G:G) -> 5 | H125: =SUMIF('Bigger Board'!D:D,D125,'Bigger Board'!H:H) -> 91.9 | I125: 76 | J125: Pittsburgh Steelers
A126: =SUMIF('Bigger Board'!D:D,D126,'Bigger Board'!A:A) -> 122 | B126: =SUMIF('Bigger Board'!D:D,D126,'Bigger Board'!B:B) -> 144 | C126: =SUMIF('Bigger Board'!D:D,D126,'Bigger Board'!C:C) -> 123 | D126: V.J. Payne | E126: Kansas State | F126: S | G126: =SUMIF('Bigger Board'!D:D,D126,'Bigger Board'!G:G) -> 10 | H126: =SUMIF('Bigger Board'!D:D,D126,'Bigger Board'!H:H) -> 106.8 | I126: 228 | J126: New York Jets
A127: =SUMIF('Bigger Board'!D:D,D127,'Bigger Board'!A:A) -> 123 | B127: =SUMIF('Bigger Board'!D:D,D127,'Bigger Board'!B:B) -> 129 | C127: =SUMIF('Bigger Board'!D:D,D127,'Bigger Board'!C:C) -> 126 | D127: Kaleb Proctor | E127: SE Louisiana | F127: DL5T | G127: =SUMIF('Bigger Board'!D:D,D127,'Bigger Board'!G:G) -> 1 | H127: =SUMIF('Bigger Board'!D:D,D127,'Bigger Board'!H:H) -> 104.6 | I127: 104 | J127: Arizona Cardinals
A128: =SUMIF('Bigger Board'!D:D,D128,'Bigger Board'!A:A) -> 124 | B128: =SUMIF('Bigger Board'!D:D,D128,'Bigger Board'!B:B) -> 116 | C128: =SUMIF('Bigger Board'!D:D,D128,'Bigger Board'!C:C) -> 128 | D128: Dametrious Crownover | E128: Texas A&M | F128: OT | G128: =SUMIF('Bigger Board'!D:D,D128,'Bigger Board'!G:G) -> 11 | H128: =SUMIF('Bigger Board'!D:D,D128,'Bigger Board'!H:H) -> 94.2 | I128: 196 | J128: New England Patriots
A129: =SUMIF('Bigger Board'!D:D,D129,'Bigger Board'!A:A) -> 125 | B129: =SUMIF('Bigger Board'!D:D,D129,'Bigger Board'!B:B) -> 140 | C129: =SUMIF('Bigger Board'!D:D,D129,'Bigger Board'!C:C) -> 125 | D129: Billy Schrauth | E129: Notre Dame | F129: OG | G129: =SUMIF('Bigger Board'!D:D,D129,'Bigger Board'!G:G) -> 7 | H129: =SUMIF('Bigger Board'!D:D,D129,'Bigger Board'!H:H) -> 83.4 | I129: 160 | J129: Tampa Bay Buccaneers
A130: =SUMIF('Bigger Board'!D:D,D130,'Bigger Board'!A:A) -> 126 | B130: =SUMIF('Bigger Board'!D:D,D130,'Bigger Board'!B:B) -> 142 | C130: =SUMIF('Bigger Board'!D:D,D130,'Bigger Board'!C:C) -> 121 | D130: Eli Raridon | E130: Notre Dame | F130: TE | G130: =SUMIF('Bigger Board'!D:D,D130,'Bigger Board'!G:G) -> 8 | H130: =SUMIF('Bigger Board'!D:D,D130,'Bigger Board'!H:H) -> 95.6 | I130: 95 | J130: New England Patriots
A131: =SUMIF('Bigger Board'!D:D,D131,'Bigger Board'!A:A) -> 127 | B131: =SUMIF('Bigger Board'!D:D,D131,'Bigger Board'!B:B) -> 127 | C131: =SUMIF('Bigger Board'!D:D,D131,'Bigger Board'!C:C) -> 124 | D131: Cole Payton | E131: NDSU | F131: QB | G131: =SUMIF('Bigger Board'!D:D,D131,'Bigger Board'!G:G) -> 6 | H131: =SUMIF('Bigger Board'!D:D,D131,'Bigger Board'!H:H) -> 101 | I131: 178 | J131: Philadelphia Eagles
A132: =SUMIF('Bigger Board'!D:D,D132,'Bigger Board'!A:A) -> 128 | B132: =SUMIF('Bigger Board'!D:D,D132,'Bigger Board'!B:B) -> 158 | C132: =SUMIF('Bigger Board'!D:D,D132,'Bigger Board'!C:C) -> 127 | D132: Jack Endries | E132: Texas | F132: TE | G132: =SUMIF('Bigger Board'!D:D,D132,'Bigger Board'!G:G) -> 9 | H132: =SUMIF('Bigger Board'!D:D,D132,'Bigger Board'!H:H) -> 101.4 | I132: 221 | J132: Cincinnati Bengals
A133: =SUMIF('Bigger Board'!D:D,D133,'Bigger Board'!A:A) -> 129 | B133: =SUMIF('Bigger Board'!D:D,D133,'Bigger Board'!B:B) -> 125 | C133: =SUMIF('Bigger Board'!D:D,D133,'Bigger Board'!C:C) -> 135 | D133: Tyler Onyedim | E133: Texas A&M | F133: DL5T | G133: =SUMIF('Bigger Board'!D:D,D133,'Bigger Board'!G:G) -> 2 | H133: =SUMIF('Bigger Board'!D:D,D133,'Bigger Board'!H:H) -> 116.3 | I133: 66 | J133: Denver Broncos
A134: =SUMIF('Bigger Board'!D:D,D134,'Bigger Board'!A:A) -> 130 | B134: =SUMIF('Bigger Board'!D:D,D134,'Bigger Board'!B:B) -> 135 | C134: =SUMIF('Bigger Board'!D:D,D134,'Bigger Board'!C:C) -> 129 | D134: Kaytron Allen | E134: Penn State | F134: RB | G134: =SUMIF('Bigger Board'!D:D,D134,'Bigger Board'!G:G) -> 6 | H134: =SUMIF('Bigger Board'!D:D,D134,'Bigger Board'!H:H) -> 81.1 | I134: 187 | J134: Washington Commanders
... A145: =SUMIF('Bigger Board'!D:D,D145,'Bigger Board'!A:A) -> 141 | B145: =SUMIF('Bigger Board'!D:D,D145,'Bigger Board'!B:B) -> 177 | C145: =SUMIF('Bigger Board'!D:D,D145,'Bigger Board'!C:C) -> 134 | D145: Ephesians Prysock | E145: Washington | F145: CB | G145: =SUMIF('Bigger Board'!D:D,D145,'Bigger Board'!G:G) -> 19 | H145: =SUMIF('Bigger Board'!D:D,D145,'Bigger Board'!H:H) -> 94.6 | I145: 139 | J145: San Francisco 49ers
A146: =SUMIF('Bigger Board'!D:D,D146,'Bigger Board'!A:A) -> 142 | B146: =SUMIF('Bigger Board'!D:D,D146,'Bigger Board'!B:B) -> 163 | C146: =SUMIF('Bigger Board'!D:D,D146,'Bigger Board'!C:C) -> 133 | D146: Dontay Corleone | E146: Cincinnati | F146: DL1T | G146: =SUMIF('Bigger Board'!D:D,D146,'Bigger Board'!G:G) -> 6 | H146: =SUMIF('Bigger Board'!D:D,D146,'Bigger Board'!H:H) -> 109.1
A147: =SUMIF('Bigger Board'!D:D,D147,'Bigger Board'!A:A) -> 143 | B147: =SUMIF('Bigger Board'!D:D,D147,'Bigger Board'!B:B) -> 162 | C147: =SUMIF('Bigger Board'!D:D,D147,'Bigger Board'!C:C) -> 142 | D147: Jadon Canady | E147: Oregon | F147: CB | G147: =SUMIF('Bigger Board'!D:D,D147,'Bigger Board'!G:G) -> 20 | H147: =SUMIF('Bigger Board'!D:D,D147,'Bigger Board'!H:H) -> 94.6 | I147: 109 | J147: Kansas City Chiefs
A148: =SUMIF('Bigger Board'!D:D,D148,'Bigger Board'!A:A) -> 144 | B148: =SUMIF('Bigger Board'!D:D,D148,'Bigger Board'!B:B) -> 154 | C148: =SUMIF('Bigger Board'!D:D,D148,'Bigger Board'!C:C) -> 148 | D148: Demond Claiborne | E148: Wake Forest | F148: RB | G148: =SUMIF('Bigger Board'!D:D,D148,'Bigger Board'!G:G) -> 8 | H148: =SUMIF('Bigger Board'!D:D,D148,'Bigger Board'!H:H) -> 84.7 | I148: 198 | J148: Minnesota Vikings
A149: =SUMIF('Bigger Board'!D:D,D149,'Bigger Board'!A:A) -> 145 | B149: =SUMIF('Bigger Board'!D:D,D149,'Bigger Board'!B:B) -> 181 | C149: =SUMIF('Bigger Board'!D:D,D149,'Bigger Board'!C:C) -> 155 | D149: Michael Taaffe | E149: Texas | F149: S | G149: =SUMIF('Bigger Board'!D:D,D149,'Bigger Board'!G:G) -> 11 | H149: =SUMIF('Bigger Board'!D:D,D149,'Bigger Board'!H:H) -> 86.1 | I149: 158 | J149: Miami Dolphins
A150: =SUMIF('Bigger Board'!D:D,D150,'Bigger Board'!A:A) -> 146 | B150: =SUMIF('Bigger Board'!D:D,D150,'Bigger Board'!B:B) -> 145 | C150: =SUMIF('Bigger Board'!D:D,D150,'Bigger Board'!C:C) -> 147 | D150: Beau Stephens | E150: Iowa | F150: OG | G150: =SUMIF('Bigger Board'!D:D,D150,'Bigger Board'!G:G) -> 9 | H150: =SUMIF('Bigger Board'!D:D,D150,'Bigger Board'!H:H) -> 89.7 | I150: 148 | J150: Seattle Seahawks
A151: =SUMIF('Bigger Board'!D:D,D151,'Bigger Board'!A:A) -> 147 | B151: =SUMIF('Bigger Board'!D:D,D151,'Bigger Board'!B:B) -> 131 | C151: =SUMIF('Bigger Board'!D:D,D151,'Bigger Board'!C:C) -> 145 | D151: Bryce Boettcher | E151: Oregon | F151: LB | G151: =SUMIF('Bigger Board'!D:D,D151,'Bigger Board'!G:G) -> 13 | H151: =SUMIF('Bigger Board'!D:D,D151,'Bigger Board'!H:H) -> 91 | I151: 135 | J151: Indianapolis Colts
A152: =SUMIF('Bigger Board'!D:D,D152,'Bigger Board'!A:A) -> 148 | B152: =SUMIF('Bigger Board'!D:D,D152,'Bigger Board'!B:B) -> 132 | C152: =SUMIF('Bigger Board'!D:D,D152,'Bigger Board'!C:C) -> 153 | D152: Taylen Green | E152: Arkansas | F152: QB | G152: =SUMIF('Bigger Board'!D:D,D152,'Bigger Board'!G:G) -> 7 | H152: =SUMIF('Bigger Board'!D:D,D152,'Bigger Board'!H:H) -> 105 | I152: 182 | J152: Cleveland Browns
A153: =SUMIF('Bigger Board'!D:D,D153,'Bigger Board'!A:A) -> 149 | B153: =SUMIF('Bigger Board'!D:D,D153,'Bigger Board'!B:B) -> 165 | C153: =SUMIF('Bigger Board'!D:D,D153,'Bigger Board'!C:C) -> 157 | D153: Aiden Fisher | E153: Indiana | F153: LB | G153: =SUMIF('Bigger Board'!D:D,D153,'Bigger Board'!G:G) -> 14 | H153: =SUMIF('Bigger Board'!D:D,D153,'Bigger Board'!H:H) -> 90.6 | I153: 243 | J153: Houston Texans
...

Sheet Big Board (by pick)
A1: Pick | B1: Rk | E1: Player | F1: School | G1: Position | H1: Pos Rk | I1: Variance | J1: Pick | K1: Team
A2: =IF(SUMIF('Big Board (by rank)'!D:D,E2,'Big Board (by rank)'!I:I)=0,"",SUMIF('Big Board (by rank)'!D:D,E2,'Big Board (by rank)'!I:I)) -> 1 | B2: {=SORT('Big Board (by rank)'!A5:J329,9,TRUE,1,TRUE)} -> 1 | C2: 1 | D2: 1 | E2: Fernando Mendoza | F2: Indiana | G2: QB | H2: 1 | I2: 99.1 | J2: 1 | K2: Las Vegas Raiders
A3: =IF(SUMIF('Big Board (by rank)'!D:D,E3,'Big Board (by rank)'!I:I)=0,"",SUMIF('Big Board (by rank)'!D:D,E3,'Big Board (by rank)'!I:I)) -> 2 | B3: 7 | C3: 4 | D3: 7 | E3: David Bailey | F3: Texas Tech | G3: EDGE | H3: 2 | I3: 86 | J3: 2 | K3: New York Jets
A4: =IF(SUMIF('Big Board (by rank)'!D:D,E4,'Big Board (by rank)'!I:I)=0,"",SUMIF('Big Board (by rank)'!D:D,E4,'Big Board (by rank)'!I:I)) -> 3 | B4: 3 | C4: 3 | D4: 2 | E4: Jeremiyah Love | F4: Notre Dame | G4: RB | H4: 1 | I4: 76.5 | J4: 3 | K4: Arizona Cardinals
A5: =IF(SUMIF('Big Board (by rank)'!D:D,E5,'Big Board (by rank)'!I:I)=0,"",SUMIF('Big Board (by rank)'!D:D,E5,'Big Board (by rank)'!I:I)) -> 4 | B5: 9 | C5: 9 | D5: 9 | E5: Carnell Tate | F5: Ohio State | G5: WR | H5: 1 | I5: 79.2 | J5: 4 | K5: Tennessee Titans
A6: =IF(SUMIF('Big Board (by rank)'!D:D,E6,'Big Board (by rank)'!I:I)=0,"",SUMIF('Big Board (by rank)'!D:D,E6,'Big Board (by rank)'!I:I)) -> 5 | B6: 2 | C6: 2 | D6: 3 | E6: Arvell Reese | F6: Ohio State | G6: LB | H6: 1 | I6: 75.7 | J6: 5 | K6: New York Giants
A7: =IF(SUMIF('Big Board (by rank)'!D:D,E7,'Big Board (by rank)'!I:I)=0,"",SUMIF('Big Board (by rank)'!D:D,E7,'Big Board (by rank)'!I:I)) -> 6 | B7: 10 | C7: 10 | D7: 8 | E7: Mansoor Delane | F7: LSU | G7: CB | H7: 1 | I7: 71.1 | J7: 6 | K7: Kansas City Chiefs
A8: =IF(SUMIF('Big Board (by rank)'!D:D,E8,'Big Board (by rank)'!I:I)=0,"",SUMIF('Big Board (by rank)'!D:D,E8,'Big Board (by rank)'!I:I)) -> 7 | B8: 5 | C8: 6 | D8: 5 | E8: Sonny Styles | F8: Ohio State | G8: LB | H8: 2 | I8: 76.5 | J8: 7 | K8: Washington Commanders
A9: =IF(SUMIF('Big Board (by rank)'!D:D,E9,'Big Board (by rank)'!I:I)=0,"",SUMIF('Big Board (by rank)'!D:D,E9,'Big Board (by rank)'!I:I)) -> 8 | B9: 15 | C9: 15 | D9: 12 | E9: Jordyn Tyson | F9: Arizona State | G9: WR | H9: 3 | I9: 83.3 | J9: 8 | K9: New Orleans Saints
A10: =IF(SUMIF('Big Board (by rank)'!D:D,E10,'Big Board (by rank)'!I:I)=0,"",SUMIF('Big Board (by rank)'!D:D,E10,'Big Board (by rank)'!I:I)) -> 9 | B10: 11 | C10: 11 | D10: 11 | E10: Spencer Fano | F10: Utah | G10: OT | H10: 2 | I10: 84.2 | J10: 9 | K10: Cleveland Browns
A11: =IF(SUMIF('Big Board (by rank)'!D:D,E11,'Big Board (by rank)'!I:I)=0,"",SUMIF('Big Board (by rank)'!D:D,E11,'Big Board (by rank)'!I:I)) -> 10 | B11: 8 | C11: 7 | D11: 10 | E11: Francis Mauigoa | F11: Miami (FL) | G11: OT | H11: 1 | I11: 79.2 | J11: 10 | K11: New York Giants
A12: =IF(SUMIF('Big Board (by rank)'!D:D,E12,'Big Board (by rank)'!I:I)=0,"",SUMIF('Big Board (by rank)'!D:D,E12,'Big Board (by rank)'!I:I)) -> 11 | B12: 4 | C12: 5 | D12: 4 | E12: Caleb Downs | F12: Ohio State | G12: S | H12: 1 | I12: 79.7 | J12: 11 | K12: Dallas Cowboys
A13: =IF(SUMIF('Big Board (by rank)'!D:D,E13,'Big Board (by rank)'!I:I)=0,"",SUMIF('Big Board (by rank)'!D:D,E13,'Big Board (by rank)'!I:I)) -> 12 | B13: 19 | C13: 18 | D13: 19 | E13: Kadyn Proctor | F13: Alabama | G13: OT | H13: 4 | I13: 106.4 | J13: 12 | K13: Miami Dolphins
A14: =IF(SUMIF('Big Board (by rank)'!D:D,E14,'Big Board (by rank)'!I:I)=0,"",SUMIF('Big Board (by rank)'!D:D,E14,'Big Board (by rank)'!I:I)) -> 13 | B14: 38 | C14: 35 | D14: 38 | E14: Ty Simpson | F14: Alabama | G14: QB | H14: 2 | I14: 105.1 | J14: 13 | K14: Los Angeles Rams
... A258: =IF(SUMIF('Big Board (by rank)'!D:D,E258,'Big Board (by rank)'!I:I)=0,"",SUMIF('Big Board (by rank)'!D:D,E258,'Big Board (by rank)'!I:I)) -> 257 | B258: 197 | C258: 229 | D258: 190 | E258: Red Murdock | F258: Buffalo | G258: LB | H258: 18 | I258: 91.9 | J258: 257 | K258: Denver Broncos
A259: =IF(SUMIF('Big Board (by rank)'!D:D,E259,'Big Board (by rank)'!I:I)=0,"",SUMIF('Big Board (by rank)'!D:D,E259,'Big Board (by rank)'!I:I)) | B259: 117 | C259: 137 | D259: 115 | E259: Deontae Lawson | F259: Alabama | G259: LB | H259: 9 | I259: 116.8
A260: =IF(SUMIF('Big Board (by rank)'!D:D,E260,'Big Board (by rank)'!I:I)=0,"",SUMIF('Big Board (by rank)'!D:D,E260,'Big Board (by rank)'!I:I)) | B260: 118 | C260: 118 | D260: 116 | E260: Michael Trigg | F260: Baylor | G260: TE | H260: 7 | I260: 101
A261: =IF(SUMIF('Big Board (by rank)'!D:D,E261,'Big Board (by rank)'!I:I)=0,"",SUMIF('Big Board (by rank)'!D:D,E261,'Big Board (by rank)'!I:I)) | B261: 142 | C261: 163 | D261: 133 | E261: Dontay Corleone | F261: Cincinnati | G261: DL1T | H261: 6 | I261: 109.1
A262: =IF(SUMIF('Big Board (by rank)'!D:D,E262,'Big Board (by rank)'!I:I)=0,"",SUMIF('Big Board (by rank)'!D:D,E262,'Big Board (by rank)'!I:I)) | B262: 155 | C262: 138 | D262: 156 | E262: Zxavian Harris | F262: Ole Miss | G262: DL1T | H262: 7 | I262: 99.6
A263: =IF(SUMIF('Big Board (by rank)'!D:D,E263,'Big Board (by rank)'!I:I)=0,"",SUMIF('Big Board (by rank)'!D:D,E263,'Big Board (by rank)'!I:I)) | B263: 157 | C263: 157 | D263: 158 | E263: Isaiah World | F263: Oregon | G263: OT | H263: 16 | I263: 105
A264: =IF(SUMIF('Big Board (by rank)'!D:D,E264,'Big Board (by rank)'!I:I)=0,"",SUMIF('Big Board (by rank)'!D:D,E264,'Big Board (by rank)'!I:I)) | B264: 160 | C264: 208 | D264: 143 | E264: Anthony Lucas | F264: USC | G264: EDGE | H264: 19 | I264: 107.3
A265: =IF(SUMIF('Big Board (by rank)'!D:D,E265,'Big Board (by rank)'!I:I)=0,"",SUMIF('Big Board (by rank)'!D:D,E265,'Big Board (by rank)'!I:I)) | B265: 162 | C265: 180 | D265: 144 | E265: Taurean York | F265: Texas A&M | G265: LB | H265: 15 | I265: 102.3
A266: =IF(SUMIF('Big Board (by rank)'!D:D,E266,'Big Board (by rank)'!I:I)=0,"",SUMIF('Big Board (by rank)'!D:D,E266,'Big Board (by rank)'!I:I)) | B266: 175 | C266: 190 | D266: 176 | E266: Diego Pounds | F266: Ole Miss | G266: OT | H266: 17 | I266: 103.7
A267: =IF(SUMIF('Big Board (by rank)'!D:D,E267,'Big Board (by rank)'!I:I)=0,"",SUMIF('Big Board (by rank)'!D:D,E267,'Big Board (by rank)'!I:I)) | B267: 179 | C267: 193 | D267: 174 | E267: Nadame Tucker | F267: Western Michigan | G267: EDGE | H267: 21 | I267: 91.5
A268: =IF(SUMIF('Big Board (by rank)'!D:D,E268,'Big Board (by rank)'!I:I)=0,"",SUMIF('Big Board (by rank)'!D:D,E268,'Big Board (by rank)'!I:I)) | B268: 181 | C268: 197 | D268: 183 | E268: Bishop Fitzgerald | F268: USC | G268: S | H268: 13 | I268: 80.2
A269: =IF(SUMIF('Big Board (by rank)'!D:D,E269,'Big Board (by rank)'!I:I)=0,"",SUMIF('Big Board (by rank)'!D:D,E269,'Big Board (by rank)'!I:I)) | B269: 183 | C269: 209 | D269: 187 | E269: Dae'Quan Wright | F269: Ole Miss | G269: TE | H269: 15 | I269: 82.9
A270: =IF(SUMIF('Big Board (by rank)'!D:D,E270,'Big Board (by rank)'!I:I)=0,"",SUMIF('Big Board (by rank)'!D:D,E270,'Big Board (by rank)'!I:I)) | B270: 185 | C270: 173 | D270: 192 | E270: Jeff Caldwell | F270: Cincinnati | G270: WR | H270: 25 | I270: 85.2
... A301: =IF(SUMIF('Big Board (by rank)'!D:D,E301,'Big Board (by rank)'!I:I)=0,"",SUMIF('Big Board (by rank)'!D:D,E301,'Big Board (by rank)'!I:I)) | B301: 259 | C301: 233 | D301: 262 | E301: Bryson Eason | F301: Tennessee | G301: DL1T | H301: 9 | I301: 77.9
B302: 261 | C302: 321 | D302: 247 | E302: Chase Roberts | F302: BYU | G302: WR | H302: 38 | I302: 65.7
B303: 267 | C303: 286 | D303: 268 | E303: Patrick Payton | F303: LSU | G303: EDGE | H303: 30 | I303: 73.9
B304: 268 | C304: 249 | D304: 283 | E304: Lake McRee | F304: USC | G304: TE | H304: 21 | I304: 75.7
B305: 269 | C305: 292 | D305: 263 | E305: Rene Konga | F305: Louisville | G305: DL5T | H305: 7 | I305: 107.3
B306: 270 | C306: 276 | D306: 277 | E306: Noah Whittington | F306: Oregon | G306: RB | H306: 19 | I306: 67.1
B307: 271 | C307: 257 | D307: 278 | E307: Rahsul Faison | F307: South Carolina | G307: RB | H307: 20 | I307: 72.1
B308: 272 | C308: 313 | D308: 272 | E308: Desmond Reid | F308: Pitt | G308: RB | H308: 21 | I308: 68
B309: 274 | C309: 349 | D309: 265 | E309: Nolan Rucci | F309: Penn State | G309: OT | H309: 20 | I309: 77.9
B310: 275 | C310: 258 | D310: 279 | E310: Xavian Sorey Jr. | F310: Arkansas | G310: LB | H310: 23 | I310: 64.8
B311: 276 | C311: 237 | D311: 290 | E311: Harrison Wallace III | F311: Ole Miss | G311: WR | H311: 41 | I311: 72.5
B312: 277 | C312: 306 | D312: 273 | E312: Diego Pavia | F312: Vanderbilt | G312: QB | H312: 11 | I312: 72.9
B313: 278 | C313: 234 | D313: 289 | E313: Latrell McCutchin Sr. | F313: Houston | G313: CB | H313: 30 | I313: 91.5
...

Sheet Selections
A1: Round | B1: Pick | C1: Player | D1: Pos | E1: School | F1: Rk | G1: Team
A2: 1 | B2: 1 | C2: =IFERROR(VLOOKUP(B2,'Big Board (by pick)'!A:E,5,FALSE),"") -> Fernando Mendoza | D2: =IFERROR(VLOOKUP(C2,'Big Board (by rank)'!D:F,3,FALSE),"") -> QB | E2: =IFERROR(VLOOKUP(C2,'Big Board (by rank)'!D:J,2,FALSE),"") -> Indiana | F2: =IF(SUMIF('Big Board (by rank)'!D:D,C2,'Big Board (by rank)'!A:A)=0,"",SUMIF('Big Board (by rank)'!D:D,C2,'Big Board (by rank)'!A:A)) -> 1 | G2: =IFERROR(VLOOKUP(C2,'Big Board (by rank)'!D:J,7,FALSE),"") -> Las Vegas Raiders
A3: 1 | B3: 2 | C3: =IFERROR(VLOOKUP(B3,'Big Board (by pick)'!A:E,5,FALSE),"") -> David Bailey | D3: =IFERROR(VLOOKUP(C3,'Big Board (by rank)'!D:F,3,FALSE),"") -> EDGE | E3: =IFERROR(VLOOKUP(C3,'Big Board (by rank)'!D:J,2,FALSE),"") -> Texas Tech | F3: =IF(SUMIF('Big Board (by rank)'!D:D,C3,'Big Board (by rank)'!A:A)=0,"",SUMIF('Big Board (by rank)'!D:D,C3,'Big Board (by rank)'!A:A)) -> 7 | G3: =IFERROR(VLOOKUP(C3,'Big Board (by rank)'!D:J,7,FALSE),"") -> New York Jets
A4: 1 | B4: 3 | C4: =IFERROR(VLOOKUP(B4,'Big Board (by pick)'!A:E,5,FALSE),"") -> Jeremiyah Love | D4: =IFERROR(VLOOKUP(C4,'Big Board (by rank)'!D:F,3,FALSE),"") -> RB | E4: =IFERROR(VLOOKUP(C4,'Big Board (by rank)'!D:J,2,FALSE),"") -> Notre Dame | F4: =IF(SUMIF('Big Board (by rank)'!D:D,C4,'Big Board (by rank)'!A:A)=0,"",SUMIF('Big Board (by rank)'!D:D,C4,'Big Board (by rank)'!A:A)) -> 3 | G4: =IFERROR(VLOOKUP(C4,'Big Board (by rank)'!D:J,7,FALSE),"") -> Arizona Cardinals
A5: 1 | B5: 4 | C5: =IFERROR(VLOOKUP(B5,'Big Board (by pick)'!A:E,5,FALSE),"") -> Carnell Tate | D5: =IFERROR(VLOOKUP(C5,'Big Board (by rank)'!D:F,3,FALSE),"") -> WR | E5: =IFERROR(VLOOKUP(C5,'Big Board (by rank)'!D:J,2,FALSE),"") -> Ohio State | F5: =IF(SUMIF('Big Board (by rank)'!D:D,C5,'Big Board (by rank)'!A:A)=0,"",SUMIF('Big Board (by rank)'!D:D,C5,'Big Board (by rank)'!A:A)) -> 9 | G5: =IFERROR(VLOOKUP(C5,'Big Board (by rank)'!D:J,7,FALSE),"") -> Tennessee Titans
A6: 1 | B6: 5 | C6: =IFERROR(VLOOKUP(B6,'Big Board (by pick)'!A:E,5,FALSE),"") -> Arvell Reese | D6: =IFERROR(VLOOKUP(C6,'Big Board (by rank)'!D:F,3,FALSE),"") -> LB | E6: =IFERROR(VLOOKUP(C6,'Big Board (by rank)'!D:J,2,FALSE),"") -> Ohio State | F6: =IF(SUMIF('Big Board (by rank)'!D:D,C6,'Big Board (by rank)'!A:A)=0,"",SUMIF('Big Board (by rank)'!D:D,C6,'Big Board (by rank)'!A:A)) -> 2 | G6: =IFERROR(VLOOKUP(C6,'Big Board (by rank)'!D:J,7,FALSE),"") -> New York Giants
A7: 1 | B7: 6 | C7: =IFERROR(VLOOKUP(B7,'Big Board (by pick)'!A:E,5,FALSE),"") -> Mansoor Delane | D7: =IFERROR(VLOOKUP(C7,'Big Board (by rank)'!D:F,3,FALSE),"") -> CB | E7: =IFERROR(VLOOKUP(C7,'Big Board (by rank)'!D:J,2,FALSE),"") -> LSU | F7: =IF(SUMIF('Big Board (by rank)'!D:D,C7,'Big Board (by rank)'!A:A)=0,"",SUMIF('Big Board (by rank)'!D:D,C7,'Big Board (by rank)'!A:A)) -> 10 | G7: =IFERROR(VLOOKUP(C7,'Big Board (by rank)'!D:J,7,FALSE),"") -> Kansas City Chiefs
A8: 1 | B8: 7 | C8: =IFERROR(VLOOKUP(B8,'Big Board (by pick)'!A:E,5,FALSE),"") -> Sonny Styles | D8: =IFERROR(VLOOKUP(C8,'Big Board (by rank)'!D:F,3,FALSE),"") -> LB | E8: =IFERROR(VLOOKUP(C8,'Big Board (by rank)'!D:J,2,FALSE),"") -> Ohio State | F8: =IF(SUMIF('Big Board (by rank)'!D:D,C8,'Big Board (by rank)'!A:A)=0,"",SUMIF('Big Board (by rank)'!D:D,C8,'Big Board (by rank)'!A:A)) -> 5 | G8: =IFERROR(VLOOKUP(C8,'Big Board (by rank)'!D:J,7,FALSE),"") -> Washington Commanders
A9: 1 | B9: 8 | C9: =IFERROR(VLOOKUP(B9,'Big Board (by pick)'!A:E,5,FALSE),"") -> Jordyn Tyson | D9: =IFERROR(VLOOKUP(C9,'Big Board (by rank)'!D:F,3,FALSE),"") -> WR | E9: =IFERROR(VLOOKUP(C9,'Big Board (by rank)'!D:J,2,FALSE),"") -> Arizona State | F9: =IF(SUMIF('Big Board (by rank)'!D:D,C9,'Big Board (by rank)'!A:A)=0,"",SUMIF('Big Board (by rank)'!D:D,C9,'Big Board (by rank)'!A:A)) -> 15 | G9: =IFERROR(VLOOKUP(C9,'Big Board (by rank)'!D:J,7,FALSE),"") -> New Orleans Saints
A10: 1 | B10: 9 | C10: =IFERROR(VLOOKUP(B10,'Big Board (by pick)'!A:E,5,FALSE),"") -> Spencer Fano | D10: =IFERROR(VLOOKUP(C10,'Big Board (by rank)'!D:F,3,FALSE),"") -> OT | E10: =IFERROR(VLOOKUP(C10,'Big Board (by rank)'!D:J,2,FALSE),"") -> Utah | F10: =IF(SUMIF('Big Board (by rank)'!D:D,C10,'Big Board (by rank)'!A:A)=0,"",SUMIF('Big Board (by rank)'!D:D,C10,'Big Board (by rank)'!A:A)) -> 11 | G10: =IFERROR(VLOOKUP(C10,'Big Board (by rank)'!D:J,7,FALSE),"") -> Cleveland Browns
A11: 1 | B11: 10 | C11: =IFERROR(VLOOKUP(B11,'Big Board (by pick)'!A:E,5,FALSE),"") -> Francis Mauigoa | D11: =IFERROR(VLOOKUP(C11,'Big Board (by rank)'!D:F,3,FALSE),"") -> OT | E11: =IFERROR(VLOOKUP(C11,'Big Board (by rank)'!D:J,2,FALSE),"") -> Miami (FL) | F11: =IF(SUMIF('Big Board (by rank)'!D:D,C11,'Big Board (by rank)'!A:A)=0,"",SUMIF('Big Board (by rank)'!D:D,C11,'Big Board (by rank)'!A:A)) -> 8 | G11: =IFERROR(VLOOKUP(C11,'Big Board (by rank)'!D:J,7,FALSE),"") -> New York Giants
A12: 1 | B12: 11 | C12: =IFERROR(VLOOKUP(B12,'Big Board (by pick)'!A:E,5,FALSE),"") -> Caleb Downs | D12: =IFERROR(VLOOKUP(C12,'Big Board (by rank)'!D:F,3,FALSE),"") -> S | E12: =IFERROR(VLOOKUP(C12,'Big Board (by rank)'!D:J,2,FALSE),"") -> Ohio State | F12: =IF(SUMIF('Big Board (by rank)'!D:D,C12,'Big Board (by rank)'!A:A)=0,"",SUMIF('Big Board (by rank)'!D:D,C12,'Big Board (by rank)'!A:A)) -> 4 | G12: =IFERROR(VLOOKUP(C12,'Big Board (by rank)'!D:J,7,FALSE),"") -> Dallas Cowboys
A13: 1 | B13: 12 | C13: =IFERROR(VLOOKUP(B13,'Big Board (by pick)'!A:E,5,FALSE),"") -> Kadyn Proctor | D13: =IFERROR(VLOOKUP(C13,'Big Board (by rank)'!D:F,3,FALSE),"") -> OT | E13: =IFERROR(VLOOKUP(C13,'Big Board (by rank)'!D:J,2,FALSE),"") -> Alabama | F13: =IF(SUMIF('Big Board (by rank)'!D:D,C13,'Big Board (by rank)'!A:A)=0,"",SUMIF('Big Board (by rank)'!D:D,C13,'Big Board (by rank)'!A:A)) -> 19 | G13: =IFERROR(VLOOKUP(C13,'Big Board (by rank)'!D:J,7,FALSE),"") -> Miami Dolphins
... A258: 7 | B258: 257 | C258: =IFERROR(VLOOKUP(B258,'Big Board (by pick)'!A:E,5,FALSE),"") -> Red Murdock | D258: =IFERROR(VLOOKUP(C258,'Big Board (by rank)'!D:F,3,FALSE),"") -> LB | E258: =IFERROR(VLOOKUP(C258,'Big Board (by rank)'!D:J,2,FALSE),"") -> Buffalo | F258: =IF(SUMIF('Big Board (by rank)'!D:D,C258,'Big Board (by rank)'!A:A)=0,"",SUMIF('Big Board (by rank)'!D:D,C258,'Big Board (by rank)'!A:A)) -> 197 | G258: =IFERROR(VLOOKUP(C258,'Big Board (by rank)'!D:J,7,FALSE),"") -> Denver Broncos

Sheet Team Names
A1: Arizona Cardinals | B1: 1
A2: Atlanta Falcons | B2: 2
A3: Baltimore Ravens | B3: 3
A4: Buffalo Bills | B4: 4
A5: Carolina Panthers | B5: 5
A6: Chicago Bears | B6: 6
A7: Cincinnati Bengals | B7: 7
A8: Cleveland Browns | B8: 8
A9: Dallas Cowboys | B9: 9
A10: Denver Broncos | B10: 10
A11: Detroit Lions | B11: 11
A12: Green Bay Packers | B12: 12
... A32: Washington Commanders | B32: 32
B33: 33
B34: 34
B35: 35
B36: 36
B37: 37
B38: 38
B39: 39
B40: 40
B41: 41
B42: 42
B43: 43
B44: 44
... B259: 259

Sheet Bigger Board
A1: Rank | B1: Fore | C1: Eval | D1: Player | E1: School | F1: Position | G1: Pos Rank | H1: Variance
A2: 1 | B2: 1 | C2: 1 | D2: Fernando Mendoza | E2: Indiana | F2: QB | G2: 1 | H2: 99.1
A3: 2 | B3: 2 | C3: 3 | D3: Arvell Reese | E3: Ohio State | F3: LB | G3: 1 | H3: 75.7
A4: 3 | B4: 3 | C4: 2 | D4: Jeremiyah Love | E4: Notre Dame | F4: RB | G4: 1 | H4: 76.5
A5: 4 | B5: 5 | C5: 4 | D5: Caleb Downs | E5: Ohio State | F5: S | G5: 1 | H5: 79.7
A6: 5 | B6: 6 | C6: 5 | D6: Sonny Styles | E6: Ohio State | F6: LB | G6: 2 | H6: 76.5
A7: 6 | B7: 8 | C7: 6 | D7: Rueben Bain Jr. | E7: Miami (FL) | F7: EDGE | G7: 1 | H7: 84.3
A8: 7 | B8: 4 | C8: 7 | D8: David Bailey | E8: Texas Tech | F8: EDGE | G8: 2 | H8: 86
A9: 8 | B9: 7 | C9: 10 | D9: Francis Mauigoa | E9: Miami (FL) | F9: OT | G9: 1 | H9: 79.2
A10: 9 | B10: 9 | C10: 9 | D10: Carnell Tate | E10: Ohio State | F10: WR | G10: 1 | H10: 79.2
A11: 10 | B11: 10 | C11: 8 | D11: Mansoor Delane | E11: LSU | F11: CB | G11: 1 | H11: 71.1
A12: 11 | B12: 11 | C12: 11 | D12: Spencer Fano | E12: Utah | F12: OT | G12: 2 | H12: 84.2
A13: 12 | B13: 12 | C13: 14 | D13: Makai Lemon | E13: USC | F13: WR | G13: 2 | H13: 82.4
... A837: 836 | B837: 835 | C837: 655 | D837: Tyler Van Dyke | E837: SMU | F837: QB | G837: 37 | H837: 72

Sheet Pick by Pick Grades
A1: Cons | B1: Fore | C1: Eval | D1: Player | E1: School | F1: Pos | G1: Pos Rk | H1: Pick | I1: Team | J1: Value Spent | K1: Value Gained | L1: Straight Value | M1: Value Mod | N1: Pos Mod | O1: Need Mod | P1: Mod Vl Spt | Q1: Mod Vl Gn | R1: Spend Score | S1: Value Score | T1: Net Rank | U1: Net Score
A2: =IF(SUMIF('Big Board (by rank)'!$D:$D,$D2,'Big Board (by rank)'!A:A)=0,"",SUMIF('Big Board (by rank)'!$D:$D,$D2,'Big Board (by rank)'!A:A)) | B2: =IF(SUMIF('Big Board (by rank)'!$D:$D,$D2,'Big Board (by rank)'!B:B)=0,"",SUMIF('Big Board (by rank)'!$D:$D,$D2,'Big Board (by rank)'!B:B)) | C2: =IF(SUMIF('Big Board (by rank)'!$D:$D,$D2,'Big Board (by rank)'!C:C)=0,"",SUMIF('Big Board (by rank)'!$D:$D,$D2,'Big Board (by rank)'!C:C)) | D2: =IFERROR(VLOOKUP(I2,Selections!B:C,2,FALSE),"") | E2: =IFERROR(VLOOKUP(D2,'Big Board (by rank)'!D:E,2,FALSE),"") | F2: =IFERROR(VLOOKUP(D2,'Big Board (by rank)'!D:F,2,FALSE),"") | G2: =IF(SUMIF('Big Board (by rank)'!D:D,D2,'Big Board (by rank)'!G:G)=0,"",SUMIF('Big Board (by rank)'!D:D,D2,'Big Board (by rank)'!G:G))
A3: =IF(SUMIF('Big Board (by rank)'!$D:$D,$D3,'Big Board (by rank)'!A:A)=0,"",SUMIF('Big Board (by rank)'!$D:$D,$D3,'Big Board (by rank)'!A:A)) | B3: =IF(SUMIF('Big Board (by rank)'!$D:$D,$D3,'Big Board (by rank)'!B:B)=0,"",SUMIF('Big Board (by rank)'!$D:$D,$D3,'Big Board (by rank)'!B:B)) | C3: =IF(SUMIF('Big Board (by rank)'!$D:$D,$D3,'Big Board (by rank)'!C:C)=0,"",SUMIF('Big Board (by rank)'!$D:$D,$D3,'Big Board (by rank)'!C:C)) | D3: =IFERROR(VLOOKUP(I3,Selections!B:C,2,FALSE),"") | E3: =IFERROR(VLOOKUP(D3,'Big Board (by rank)'!D:E,2,FALSE),"") | G3: =IF(SUMIF('Big Board (by rank)'!D:D,D3,'Big Board (by rank)'!G:G)=0,"",SUMIF('Big Board (by rank)'!D:D,D3,'Big Board (by rank)'!G:G))
A4: =IF(SUMIF('Big Board (by rank)'!$D:$D,$D4,'Big Board (by rank)'!A:A)=0,"",SUMIF('Big Board (by rank)'!$D:$D,$D4,'Big Board (by rank)'!A:A)) | B4: =IF(SUMIF('Big Board (by rank)'!$D:$D,$D4,'Big Board (by rank)'!B:B)=0,"",SUMIF('Big Board (by rank)'!$D:$D,$D4,'Big Board (by rank)'!B:B)) | C4: =IF(SUMIF('Big Board (by rank)'!$D:$D,$D4,'Big Board (by rank)'!C:C)=0,"",SUMIF('Big Board (by rank)'!$D:$D,$D4,'Big Board (by rank)'!C:C)) | D4: =IFERROR(VLOOKUP(I4,Selections!B:C,2,FALSE),"") | E4: =IFERROR(VLOOKUP(D4,'Big Board (by rank)'!D:E,2,FALSE),"") | G4: =IF(SUMIF('Big Board (by rank)'!D:D,D4,'Big Board (by rank)'!G:G)=0,"",SUMIF('Big Board (by rank)'!D:D,D4,'Big Board (by rank)'!G:G))
A5: =IF(SUMIF('Big Board (by rank)'!$D:$D,$D5,'Big Board (by rank)'!A:A)=0,"",SUMIF('Big Board (by rank)'!$D:$D,$D5,'Big Board (by rank)'!A:A)) | B5: =IF(SUMIF('Big Board (by rank)'!$D:$D,$D5,'Big Board (by rank)'!B:B)=0,"",SUMIF('Big Board (by rank)'!$D:$D,$D5,'Big Board (by rank)'!B:B)) | C5: =IF(SUMIF('Big Board (by rank)'!$D:$D,$D5,'Big Board (by rank)'!C:C)=0,"",SUMIF('Big Board (by rank)'!$D:$D,$D5,'Big Board (by rank)'!C:C)) | D5: =IFERROR(VLOOKUP(I5,Selections!B:C,2,FALSE),"") | E5: =IFERROR(VLOOKUP(D5,'Big Board (by rank)'!D:E,2,FALSE),"") | G5: =IF(SUMIF('Big Board (by rank)'!D:D,D5,'Big Board (by rank)'!G:G)=0,"",SUMIF('Big Board (by rank)'!D:D,D5,'Big Board (by rank)'!G:G))
A6: =IF(SUMIF('Big Board (by rank)'!$D:$D,$D6,'Big Board (by rank)'!A:A)=0,"",SUMIF('Big Board (by rank)'!$D:$D,$D6,'Big Board (by rank)'!A:A)) | B6: =IF(SUMIF('Big Board (by rank)'!$D:$D,$D6,'Big Board (by rank)'!B:B)=0,"",SUMIF('Big Board (by rank)'!$D:$D,$D6,'Big Board (by rank)'!B:B)) | C6: =IF(SUMIF('Big Board (by rank)'!$D:$D,$D6,'Big Board (by rank)'!C:C)=0,"",SUMIF('Big Board (by rank)'!$D:$D,$D6,'Big Board (by rank)'!C:C)) | D6: =IFERROR(VLOOKUP(I6,Selections!B:C,2,FALSE),"") | E6: =IFERROR(VLOOKUP(D6,'Big Board (by rank)'!D:E,2,FALSE),"") | G6: =IF(SUMIF('Big Board (by rank)'!D:D,D6,'Big Board (by rank)'!G:G)=0,"",SUMIF('Big Board (by rank)'!D:D,D6,'Big Board (by rank)'!G:G))
A7: =IF(SUMIF('Big Board (by rank)'!$D:$D,$D7,'Big Board (by rank)'!A:A)=0,"",SUMIF('Big Board (by rank)'!$D:$D,$D7,'Big Board (by rank)'!A:A)) | B7: =IF(SUMIF('Big Board (by rank)'!$D:$D,$D7,'Big Board (by rank)'!B:B)=0,"",SUMIF('Big Board (by rank)'!$D:$D,$D7,'Big Board (by rank)'!B:B)) | C7: =IF(SUMIF('Big Board (by rank)'!$D:$D,$D7,'Big Board (by rank)'!C:C)=0,"",SUMIF('Big Board (by rank)'!$D:$D,$D7,'Big Board (by rank)'!C:C)) | D7: =IFERROR(VLOOKUP(I7,Selections!B:C,2,FALSE),"") | E7: =IFERROR(VLOOKUP(D7,'Big Board (by rank)'!D:E,2,FALSE),"") | G7: =IF(SUMIF('Big Board (by rank)'!D:D,D7,'Big Board (by rank)'!G:G)=0,"",SUMIF('Big Board (by rank)'!D:D,D7,'Big Board (by rank)'!G:G))
A8: =IF(SUMIF('Big Board (by rank)'!$D:$D,$D8,'Big Board (by rank)'!A:A)=0,"",SUMIF('Big Board (by rank)'!$D:$D,$D8,'Big Board (by rank)'!A:A)) | B8: =IF(SUMIF('Big Board (by rank)'!$D:$D,$D8,'Big Board (by rank)'!B:B)=0,"",SUMIF('Big Board (by rank)'!$D:$D,$D8,'Big Board (by rank)'!B:B)) | C8: =IF(SUMIF('Big Board (by rank)'!$D:$D,$D8,'Big Board (by rank)'!C:C)=0,"",SUMIF('Big Board (by rank)'!$D:$D,$D8,'Big Board (by rank)'!C:C)) | D8: =IFERROR(VLOOKUP(I8,Selections!B:C,2,FALSE),"") | E8: =IFERROR(VLOOKUP(D8,'Big Board (by rank)'!D:E,2,FALSE),"") | G8: =IF(SUMIF('Big Board (by rank)'!D:D,D8,'Big Board (by rank)'!G:G)=0,"",SUMIF('Big Board (by rank)'!D:D,D8,'Big Board (by rank)'!G:G))
A9: =IF(SUMIF('Big Board (by rank)'!$D:$D,$D9,'Big Board (by rank)'!A:A)=0,"",SUMIF('Big Board (by rank)'!$D:$D,$D9,'Big Board (by rank)'!A:A)) | B9: =IF(SUMIF('Big Board (by rank)'!$D:$D,$D9,'Big Board (by rank)'!B:B)=0,"",SUMIF('Big Board (by rank)'!$D:$D,$D9,'Big Board (by rank)'!B:B)) | C9: =IF(SUMIF('Big Board (by rank)'!$D:$D,$D9,'Big Board (by rank)'!C:C)=0,"",SUMIF('Big Board (by rank)'!$D:$D,$D9,'Big Board (by rank)'!C:C)) | D9: =IFERROR(VLOOKUP(I9,Selections!B:C,2,FALSE),"") | E9: =IFERROR(VLOOKUP(D9,'Big Board (by rank)'!D:E,2,FALSE),"") | G9: =IF(SUMIF('Big Board (by rank)'!D:D,D9,'Big Board (by rank)'!G:G)=0,"",SUMIF('Big Board (by rank)'!D:D,D9,'Big Board (by rank)'!G:G))
A10: =IF(SUMIF('Big Board (by rank)'!$D:$D,$D10,'Big Board (by rank)'!A:A)=0,"",SUMIF('Big Board (by rank)'!$D:$D,$D10,'Big Board (by rank)'!A:A)) | B10: =IF(SUMIF('Big Board (by rank)'!$D:$D,$D10,'Big Board (by rank)'!B:B)=0,"",SUMIF('Big Board (by rank)'!$D:$D,$D10,'Big Board (by rank)'!B:B)) | C10: =IF(SUMIF('Big Board (by rank)'!$D:$D,$D10,'Big Board (by rank)'!C:C)=0,"",SUMIF('Big Board (by rank)'!$D:$D,$D10,'Big Board (by rank)'!C:C)) | D10: =IFERROR(VLOOKUP(I10,Selections!B:C,2,FALSE),"") | E10: =IFERROR(VLOOKUP(D10,'Big Board (by rank)'!D:E,2,FALSE),"") | G10: =IF(SUMIF('Big Board (by rank)'!D:D,D10,'Big Board (by rank)'!G:G)=0,"",SUMIF('Big Board (by rank)'!D:D,D10,'Big Board (by rank)'!G:G))
A11: =IF(SUMIF('Big Board (by rank)'!$D:$D,$D11,'Big Board (by rank)'!A:A)=0,"",SUMIF('Big Board (by rank)'!$D:$D,$D11,'Big Board (by rank)'!A:A)) | B11: =IF(SUMIF('Big Board (by rank)'!$D:$D,$D11,'Big Board (by rank)'!B:B)=0,"",SUMIF('Big Board (by rank)'!$D:$D,$D11,'Big Board (by rank)'!B:B)) | C11: =IF(SUMIF('Big Board (by rank)'!$D:$D,$D11,'Big Board (by rank)'!C:C)=0,"",SUMIF('Big Board (by rank)'!$D:$D,$D11,'Big Board (by rank)'!C:C)) | D11: =IFERROR(VLOOKUP(I11,Selections!B:C,2,FALSE),"") | E11: =IFERROR(VLOOKUP(D11,'Big Board (by rank)'!D:E,2,FALSE),"") | G11: =IF(SUMIF('Big Board (by rank)'!D:D,D11,'Big Board (by rank)'!G:G)=0,"",SUMIF('Big Board (by rank)'!D:D,D11,'Big Board (by rank)'!G:G))
A12: =IF(SUMIF('Big Board (by rank)'!$D:$D,$D12,'Big Board (by rank)'!A:A)=0,"",SUMIF('Big Board (by rank)'!$D:$D,$D12,'Big Board (by rank)'!A:A)) | B12: =IF(SUMIF('Big Board (by rank)'!$D:$D,$D12,'Big Board (by rank)'!B:B)=0,"",SUMIF('Big Board (by rank)'!$D:$D,$D12,'Big Board (by rank)'!B:B)) | C12: =IF(SUMIF('Big Board (by rank)'!$D:$D,$D12,'Big Board (by rank)'!C:C)=0,"",SUMIF('Big Board (by rank)'!$D:$D,$D12,'Big Board (by rank)'!C:C)) | D12: =IFERROR(VLOOKUP(I12,Selections!B:C,2,FALSE),"") | E12: =IFERROR(VLOOKUP(D12,'Big Board (by rank)'!D:E,2,FALSE),"") | G12: =IF(SUMIF('Big Board (by rank)'!D:D,D12,'Big Board (by rank)'!G:G)=0,"",SUMIF('Big Board (by rank)'!D:D,D12,'Big Board (by rank)'!G:G))
A13: =IF(SUMIF('Big Board (by rank)'!$D:$D,$D13,'Big Board (by rank)'!A:A)=0,"",SUMIF('Big Board (by rank)'!$D:$D,$D13,'Big Board (by rank)'!A:A)) | B13: =IF(SUMIF('Big Board (by rank)'!$D:$D,$D13,'Big Board (by rank)'!B:B)=0,"",SUMIF('Big Board (by rank)'!$D:$D,$D13,'Big Board (by rank)'!B:B)) | C13: =IF(SUMIF('Big Board (by rank)'!$D:$D,$D13,'Big Board (by rank)'!C:C)=0,"",SUMIF('Big Board (by rank)'!$D:$D,$D13,'Big Board (by rank)'!C:C)) | D13: =IFERROR(VLOOKUP(I13,Selections!B:C,2,FALSE),"") | E13: =IFERROR(VLOOKUP(D13,'Big Board (by rank)'!D:E,2,FALSE),"") | G13: =IF(SUMIF('Big Board (by rank)'!D:D,D13,'Big Board (by rank)'!G:G)=0,"",SUMIF('Big Board (by rank)'!D:D,D13,'Big Board (by rank)'!G:G))
A14: =IF(SUMIF('Big Board (by rank)'!$D:$D,$D14,'Big Board (by rank)'!A:A)=0,"",SUMIF('Big Board (by rank)'!$D:$D,$D14,'Big Board (by rank)'!A:A)) | B14: =IF(SUMIF('Big Board (by rank)'!$D:$D,$D14,'Big Board (by rank)'!B:B)=0,"",SUMIF('Big Board (by rank)'!$D:$D,$D14,'Big Board (by rank)'!B:B)) | C14: =IF(SUMIF('Big Board (by rank)'!$D:$D,$D14,'Big Board (by rank)'!C:C)=0,"",SUMIF('Big Board (by rank)'!$D:$D,$D14,'Big Board (by rank)'!C:C)) | D14: =IFERROR(VLOOKUP(I14,Selections!B:C,2,FALSE),"") | E14: =IFERROR(VLOOKUP(D14,'Big Board (by rank)'!D:E,2,FALSE),"") | G14: =IF(SUMIF('Big Board (by rank)'!D:D,D14,'Big Board (by rank)'!G:G)=0,"",SUMIF('Big Board (by rank)'!D:D,D14,'Big Board (by rank)'!G:G))
... A262: =IF(SUMIF('Big Board (by rank)'!$D:$D,$D262,'Big Board (by rank)'!A:A)=0,"",SUMIF('Big Board (by rank)'!$D:$D,$D262,'Big Board (by rank)'!A:A)) | B262: =IF(SUMIF('Big Board (by rank)'!$D:$D,$D262,'Big Board (by rank)'!B:B)=0,"",SUMIF('Big Board (by rank)'!$D:$D,$D262,'Big Board (by rank)'!B:B)) | C262: =IF(SUMIF('Big Board (by rank)'!$D:$D,$D262,'Big Board (by rank)'!C:C)=0,"",SUMIF('Big Board (by rank)'!$D:$D,$D262,'Big Board (by rank)'!C:C)) | D262: =IFERROR(VLOOKUP(I262,Selections!B:C,2,FALSE),"") | E262: =IFERROR(VLOOKUP(D262,'Big Board (by rank)'!D:E,2,FALSE),"") | G262: =IF(SUMIF('Big Board (by rank)'!D:D,D262,'Big Board (by rank)'!G:G)=0,"",SUMIF('Big Board (by rank)'!D:D,D262,'Big Board (by rank)'!G:G))

Sheet Team Grades
A1: Team | B1: Value Spent | C1: Value Gained | D1: % ROI | E1: % Pos | F1: % Neg | G1: % Wash
A2: Carolina Panthers | B2: =SUMIF('Pick by Pick Grades'!I:I,A2,'Pick by Pick Grades'!J:J) -> 0 | C2: =SUMIF('Pick by Pick Grades'!I:I,A2,'Pick by Pick Grades'!S:S) -> 0 | D2: =C2/B2 -> #DIV/0! | E2: =COUNTIFS('Pick by Pick Grades'!I:I,A2,'Pick by Pick Grades'!U:U,">49.9")/COUNTIF('Pick by Pick Grades'!I:I,A2) -> #DIV/0! | F2: =COUNTIFS('Pick by Pick Grades'!I:I,A2,'Pick by Pick Grades'!U:U,"<-49.9")/COUNTIF('Pick by Pick Grades'!I:I,A2) -> #DIV/0! | G2: =COUNTIFS('Pick by Pick Grades'!I:I,A2,'Pick by Pick Grades'!U:U,">-49.9",'Pick by Pick Grades'!U:U,"<49.9")/COUNTIF('Pick by Pick Grades'!I:I,A2) -> #DIV/0!
A3: Arizona Cardinals | B3: =SUMIF('Pick by Pick Grades'!I:I,A3,'Pick by Pick Grades'!J:J) -> 0 | C3: =SUMIF('Pick by Pick Grades'!I:I,A3,'Pick by Pick Grades'!S:S) -> 0 | D3: =C3/B3 -> #DIV/0! | E3: =COUNTIFS('Pick by Pick Grades'!I:I,A3,'Pick by Pick Grades'!U:U,">49.9")/COUNTIF('Pick by Pick Grades'!I:I,A3) -> #DIV/0! | F3: =COUNTIFS('Pick by Pick Grades'!I:I,A3,'Pick by Pick Grades'!U:U,"<-49.9")/COUNTIF('Pick by Pick Grades'!I:I,A3) -> #DIV/0! | G3: =COUNTIFS('Pick by Pick Grades'!I:I,A3,'Pick by Pick Grades'!U:U,">-49.9",'Pick by Pick Grades'!U:U,"<49.9")/COUNTIF('Pick by Pick Grades'!I:I,A3) -> #DIV/0!
A4: Kansas City Chiefs | B4: =SUMIF('Pick by Pick Grades'!I:I,A4,'Pick by Pick Grades'!J:J) -> 0 | C4: =SUMIF('Pick by Pick Grades'!I:I,A4,'Pick by Pick Grades'!S:S) -> 0 | D4: =C4/B4 -> #DIV/0! | E4: =COUNTIFS('Pick by Pick Grades'!I:I,A4,'Pick by Pick Grades'!U:U,">49.9")/COUNTIF('Pick by Pick Grades'!I:I,A4) -> #DIV/0! | F4: =COUNTIFS('Pick by Pick Grades'!I:I,A4,'Pick by Pick Grades'!U:U,"<-49.9")/COUNTIF('Pick by Pick Grades'!I:I,A4) -> #DIV/0! | G4: =COUNTIFS('Pick by Pick Grades'!I:I,A4,'Pick by Pick Grades'!U:U,">-49.9",'Pick by Pick Grades'!U:U,"<49.9")/COUNTIF('Pick by Pick Grades'!I:I,A4) -> #DIV/0!
A5: Seattle Seahawks | B5: =SUMIF('Pick by Pick Grades'!I:I,A5,'Pick by Pick Grades'!J:J) -> 0 | C5: =SUMIF('Pick by Pick Grades'!I:I,A5,'Pick by Pick Grades'!S:S) -> 0 | D5: =C5/B5 -> #DIV/0! | E5: =COUNTIFS('Pick by Pick Grades'!I:I,A5,'Pick by Pick Grades'!U:U,">49.9")/COUNTIF('Pick by Pick Grades'!I:I,A5) -> #DIV/0! | F5: =COUNTIFS('Pick by Pick Grades'!I:I,A5,'Pick by Pick Grades'!U:U,"<-49.9")/COUNTIF('Pick by Pick Grades'!I:I,A5) -> #DIV/0! | G5: =COUNTIFS('Pick by Pick Grades'!I:I,A5,'Pick by Pick Grades'!U:U,">-49.9",'Pick by Pick Grades'!U:U,"<49.9")/COUNTIF('Pick by Pick Grades'!I:I,A5) -> #DIV/0!
A6: Baltimore Ravens | B6: =SUMIF('Pick by Pick Grades'!I:I,A6,'Pick by Pick Grades'!J:J) -> 0 | C6: =SUMIF('Pick by Pick Grades'!I:I,A6,'Pick by Pick Grades'!S:S) -> 0 | D6: =C6/B6 -> #DIV/0! | E6: =COUNTIFS('Pick by Pick Grades'!I:I,A6,'Pick by Pick Grades'!U:U,">49.9")/COUNTIF('Pick by Pick Grades'!I:I,A6) -> #DIV/0! | F6: =COUNTIFS('Pick by Pick Grades'!I:I,A6,'Pick by Pick Grades'!U:U,"<-49.9")/COUNTIF('Pick by Pick Grades'!I:I,A6) -> #DIV/0! | G6: =COUNTIFS('Pick by Pick Grades'!I:I,A6,'Pick by Pick Grades'!U:U,">-49.9",'Pick by Pick Grades'!U:U,"<49.9")/COUNTIF('Pick by Pick Grades'!I:I,A6) -> #DIV/0!
A7: Cleveland Browns | B7: =SUMIF('Pick by Pick Grades'!I:I,A7,'Pick by Pick Grades'!J:J) -> 0 | C7: =SUMIF('Pick by Pick Grades'!I:I,A7,'Pick by Pick Grades'!S:S) -> 0 | D7: =C7/B7 -> #DIV/0! | E7: =COUNTIFS('Pick by Pick Grades'!I:I,A7,'Pick by Pick Grades'!U:U,">49.9")/COUNTIF('Pick by Pick Grades'!I:I,A7) -> #DIV/0! | F7: =COUNTIFS('Pick by Pick Grades'!I:I,A7,'Pick by Pick Grades'!U:U,"<-49.9")/COUNTIF('Pick by Pick Grades'!I:I,A7) -> #DIV/0! | G7: =COUNTIFS('Pick by Pick Grades'!I:I,A7,'Pick by Pick Grades'!U:U,">-49.9",'Pick by Pick Grades'!U:U,"<49.9")/COUNTIF('Pick by Pick Grades'!I:I,A7) -> #DIV/0!
A8: Atlanta Falcons | B8: =SUMIF('Pick by Pick Grades'!I:I,A8,'Pick by Pick Grades'!J:J) -> 0 | C8: =SUMIF('Pick by Pick Grades'!I:I,A8,'Pick by Pick Grades'!S:S) -> 0 | D8: =C8/B8 -> #DIV/0! | E8: =COUNTIFS('Pick by Pick Grades'!I:I,A8,'Pick by Pick Grades'!U:U,">49.9")/COUNTIF('Pick by Pick Grades'!I:I,A8) -> #DIV/0! | F8: =COUNTIFS('Pick by Pick Grades'!I:I,A8,'Pick by Pick Grades'!U:U,"<-49.9")/COUNTIF('Pick by Pick Grades'!I:I,A8) -> #DIV/0! | G8: =COUNTIFS('Pick by Pick Grades'!I:I,A8,'Pick by Pick Grades'!U:U,">-49.9",'Pick by Pick Grades'!U:U,"<49.9")/COUNTIF('Pick by Pick Grades'!I:I,A8) -> #DIV/0!
A9: Las Vegas Raiders | B9: =SUMIF('Pick by Pick Grades'!I:I,A9,'Pick by Pick Grades'!J:J) -> 0 | C9: =SUMIF('Pick by Pick Grades'!I:I,A9,'Pick by Pick Grades'!S:S) -> 0 | D9: =C9/B9 -> #DIV/0! | E9: =COUNTIFS('Pick by Pick Grades'!I:I,A9,'Pick by Pick Grades'!U:U,">49.9")/COUNTIF('Pick by Pick Grades'!I:I,A9) -> #DIV/0! | F9: =COUNTIFS('Pick by Pick Grades'!I:I,A9,'Pick by Pick Grades'!U:U,"<-49.9")/COUNTIF('Pick by Pick Grades'!I:I,A9) -> #DIV/0! | G9: =COUNTIFS('Pick by Pick Grades'!I:I,A9,'Pick by Pick Grades'!U:U,">-49.9",'Pick by Pick Grades'!U:U,"<49.9")/COUNTIF('Pick by Pick Grades'!I:I,A9) -> #DIV/0!
A10: New York Jets | B10: =SUMIF('Pick by Pick Grades'!I:I,A10,'Pick by Pick Grades'!J:J) -> 0 | C10: =SUMIF('Pick by Pick Grades'!I:I,A10,'Pick by Pick Grades'!S:S) -> 0 | D10: =C10/B10 -> #DIV/0! | E10: =COUNTIFS('Pick by Pick Grades'!I:I,A10,'Pick by Pick Grades'!U:U,">49.9")/COUNTIF('Pick by Pick Grades'!I:I,A10) -> #DIV/0! | F10: =COUNTIFS('Pick by Pick Grades'!I:I,A10,'Pick by Pick Grades'!U:U,"<-49.9")/COUNTIF('Pick by Pick Grades'!I:I,A10) -> #DIV/0! | G10: =COUNTIFS('Pick by Pick Grades'!I:I,A10,'Pick by Pick Grades'!U:U,">-49.9",'Pick by Pick Grades'!U:U,"<49.9")/COUNTIF('Pick by Pick Grades'!I:I,A10) -> #DIV/0!
A11: Green Bay Packers | B11: =SUMIF('Pick by Pick Grades'!I:I,A11,'Pick by Pick Grades'!J:J) -> 0 | C11: =SUMIF('Pick by Pick Grades'!I:I,A11,'Pick by Pick Grades'!S:S) -> 0 | D11: =C11/B11 -> #DIV/0! | E11: =COUNTIFS('Pick by Pick Grades'!I:I,A11,'Pick by Pick Grades'!U:U,">49.9")/COUNTIF('Pick by Pick Grades'!I:I,A11) -> #DIV/0! | F11: =COUNTIFS('Pick by Pick Grades'!I:I,A11,'Pick by Pick Grades'!U:U,"<-49.9")/COUNTIF('Pick by Pick Grades'!I:I,A11) -> #DIV/0! | G11: =COUNTIFS('Pick by Pick Grades'!I:I,A11,'Pick by Pick Grades'!U:U,">-49.9",'Pick by Pick Grades'!U:U,"<49.9")/COUNTIF('Pick by Pick Grades'!I:I,A11) -> #DIV/0!
A12: Tennessee Titans | B12: =SUMIF('Pick by Pick Grades'!I:I,A12,'Pick by Pick Grades'!J:J) -> 0 | C12: =SUMIF('Pick by Pick Grades'!I:I,A12,'Pick by Pick Grades'!S:S) -> 0 | D12: =C12/B12 -> #DIV/0! | E12: =COUNTIFS('Pick by Pick Grades'!I:I,A12,'Pick by Pick Grades'!U:U,">49.9")/COUNTIF('Pick by Pick Grades'!I:I,A12) -> #DIV/0! | F12: =COUNTIFS('Pick by Pick Grades'!I:I,A12,'Pick by Pick Grades'!U:U,"<-49.9")/COUNTIF('Pick by Pick Grades'!I:I,A12) -> #DIV/0! | G12: =COUNTIFS('Pick by Pick Grades'!I:I,A12,'Pick by Pick Grades'!U:U,">-49.9",'Pick by Pick Grades'!U:U,"<49.9")/COUNTIF('Pick by Pick Grades'!I:I,A12) -> #DIV/0!
A13: Dallas Cowboys | B13: =SUMIF('Pick by Pick Grades'!I:I,A13,'Pick by Pick Grades'!J:J) -> 0 | C13: =SUMIF('Pick by Pick Grades'!I:I,A13,'Pick by Pick Grades'!S:S) -> 0 | D13: =C13/B13 -> #DIV/0! | E13: =COUNTIFS('Pick by Pick Grades'!I:I,A13,'Pick by Pick Grades'!U:U,">49.9")/COUNTIF('Pick by Pick Grades'!I:I,A13) -> #DIV/0! | F13: =COUNTIFS('Pick by Pick Grades'!I:I,A13,'Pick by Pick Grades'!U:U,"<-49.9")/COUNTIF('Pick by Pick Grades'!I:I,A13) -> #DIV/0! | G13: =COUNTIFS('Pick by Pick Grades'!I:I,A13,'Pick by Pick Grades'!U:U,">-49.9",'Pick by Pick Grades'!U:U,"<49.9")/COUNTIF('Pick by Pick Grades'!I:I,A13) -> #DIV/0!
... A33: New England Patriots | B33: =SUMIF('Pick by Pick Grades'!I:I,A33,'Pick by Pick Grades'!J:J) -> 0 | C33: =SUMIF('Pick by Pick Grades'!I:I,A33,'Pick by Pick Grades'!S:S) -> 0 | D33: =C33/B33 -> #DIV/0! | E33: =COUNTIFS('Pick by Pick Grades'!I:I,A33,'Pick by Pick Grades'!U:U,">49.9")/COUNTIF('Pick by Pick Grades'!I:I,A33) -> #DIV/0! | F33: =COUNTIFS('Pick by Pick Grades'!I:I,A33,'Pick by Pick Grades'!U:U,"<-49.9")/COUNTIF('Pick by Pick Grades'!I:I,A33) -> #DIV/0! | G33: =COUNTIFS('Pick by Pick Grades'!I:I,A33,'Pick by Pick Grades'!U:U,">-49.9",'Pick by Pick Grades'!U:U,"<49.9")/COUNTIF('Pick by Pick Grades'!I:I,A33) -> #DIV/0!
